<?xml version="1.0" ?>
<robot name="pars">
  <material name="blue">
    <color rgba="0 0 1 1"/>
  </material>

  <material name="black">
    <color rgba="0 0 0 1"/>
  </material>

  <material name="white">
    <color rgba="1 1 1 1"/>
  </material>

  <material name="red">
    <color rgba="0.8 0 0 1"/>
  </material>

  <material name="green">
    <color rgba="0 1 0 1"/>
  </material>

  <material name="yellow">
    <color rgba="1 1 0 1"/>
  </material>
    
  
  <link name="pars__body">
    <inertial>
      <mass value="92.0"/>
      <origin rpy="0 0 0" xyz="0  0  0.6"/>
      <inertia ixx="0.7" ixy="0" ixz="0" iyy="0.2" iyz="0" izz="0.8"/>
    </inertial>
    <collision name="pars__base_link_inertia_collision">
      <origin rpy="0 0 1.5707" xyz="0   0   0.13"/>
      <geometry>
        <mesh filename="package://angelshark_sim/models/angelshark/meshes/pars.stl" scale="0.16 0.16 0.16"/>
      </geometry>
    </collision>
    <visual name="pars__base_link_inertia_visual">
      <origin rpy="0 0 1.5707" xyz="0   0   0.13"/>
      <geometry>
        <mesh filename="package://angelshark_sim/models/angelshark/meshes/pars.stl" scale="0.16 0.16 0.16"/>
      </geometry>
    </visual>
  </link>
  <link name="pars__front_left_wheel">
    <inertial>
      <mass value="1.0"/>
      <origin rpy="0 0 0" xyz="0 0 0"/>
      <inertia ixx="0.03" ixy="0.00" ixz="0.00" iyy="0.03" iyz="0.00" izz="0.058"/>
    </inertial>
    <collision name="pars__collision">
      <origin rpy="0 0 0" xyz="0 0 0"/>
      <geometry>
        <cylinder length=".05" radius=".2932"/>
      </geometry>
    </collision>
    <visual name="pars__visual">
      <origin rpy="0 0 0" xyz="0 0 0"/>
      <geometry>
        <cylinder length=".05" radius=".2932"/>
      </geometry>
    </visual>
  </link>
  <link name="pars__front_right_wheel">
    <inertial>
      <mass value="1.0"/>
      <origin rpy="0 0 0" xyz="0 0 0"/>
      <inertia ixx="0.03" ixy="0.00" ixz="0.00" iyy="0.03" iyz="0.00" izz="0.058"/>
    </inertial>
    <collision name="pars__collision">
      <origin rpy="0 0 0" xyz="0 0 0"/>
      <geometry>
        <cylinder length=".05" radius=".2932"/>
      </geometry>
    </collision>
    <visual name="pars__visual">
      <origin rpy="0 0 0" xyz="0 0 0"/>
      <geometry>
        <cylinder length=".05" radius=".2932"/>
      </geometry>
    </visual>
  </link>
  <link name="pars__rear_left_wheel">
    <inertial>
      <mass value="2.0"/>
      <origin rpy="0 0 0" xyz="0 0 0"/>
      <inertia ixx="0.03" ixy="0.00" ixz="0.00" iyy="0.03" iyz="0.00" izz="0.058"/>
    </inertial>
    <collision name="pars__collision">
      <origin rpy="0 0 0" xyz="0 0 0"/>
      <geometry>
        <cylinder length=".05" radius=".2932"/>
      </geometry>
    </collision>
    <visual name="pars__visual">
      <origin rpy="0 0 0" xyz="0 0 0"/>
      <geometry>
        <cylinder length=".05" radius=".2932"/>
      </geometry>
    </visual>
  </link>
  <link name="pars__rear_right_wheel">
    <inertial>
      <mass value="2.0"/>
      <origin rpy="0 0 0" xyz="0 0 0"/>
      <inertia ixx="0.03" ixy="0.00" ixz="0.00" iyy="0.03" iyz="0.00" izz="0.058"/>
    </inertial>
    <collision name="pars__collision">
      <origin rpy="0 0 0" xyz="0 0 0"/>
      <geometry>
        <cylinder length=".05" radius=".2932"/>
      </geometry>
    </collision>
    <visual name="pars__visual">
      <origin rpy="0 0 0" xyz="0 0 0"/>
      <geometry>
        <cylinder length=".05" radius=".2932"/>
      </geometry>
    </visual>
  </link>
  <link name="pars__FLwheel_steer">
    <inertial>
      <mass value="1.0"/>
      <origin rpy="0 0 0" xyz="0 0 0"/>
      <inertia ixx="0.03" ixy="0.00" ixz="0.00" iyy="0.03" iyz="0.00" izz="0.058"/>
    </inertial>
  </link>
  <link name="pars__FRwheel_steer">
    <inertial>
      <mass value="1.0"/>
      <origin rpy="0 0 0" xyz="0 0 0"/>
      <inertia ixx="0.03" ixy="0.00" ixz="0.00" iyy="0.03" iyz="0.00" izz="0.058"/>
    </inertial>
  </link>
  
  <joint name="pars__jFRsteer" type="revolute">
    <parent link="pars__body"/>
    <child link="pars__FRwheel_steer"/>
    <origin rpy="0     1.5707 0" xyz="0.55 0.74 0.3"/>
    <axis xyz="1 0 0"/>
    <limit effort="10.0" lower="-1.0" upper="1.0" velocity="30"/>
  </joint>
  <joint name="pars__jFLsteer" type="revolute">
    <parent link="pars__body"/>
    <child link="pars__FLwheel_steer"/>
    <origin rpy="0     1.5707 0" xyz="-0.55  0.74  0.3"/>
    <axis xyz="1 0 0"/>
    <limit effort="10.0" lower="-1.0" upper="1.0" velocity="30"/>
  </joint>
  <joint name="pars__jFR" type="continuous">
    <parent link="pars__FRwheel_steer"/>
    <child link="pars__front_right_wheel"/>
    <origin rpy="0 0 0" xyz="0 0 0"/>
    <axis xyz="0 0 -1"/>
    <limit effort="1000" velocity="30"/>
  </joint>
  <joint name="pars__jFL" type="continuous">
    <parent link="pars__FLwheel_steer"/>
    <child link="pars__front_left_wheel"/>
    <origin rpy="0 0 0" xyz="0 0 0"/>
    <axis xyz="0 0 -1"/>
    <limit effort="1000" velocity="30"/>
  </joint>
  <joint name="pars__jRR" type="continuous">
    <parent link="pars__body"/>
    <child link="pars__rear_right_wheel"/>
    <origin rpy="0     1.5707 0" xyz="0.3 -0.7  0.3"/>
    <axis xyz="0 0 -1"/>
    <limit effort="1000" velocity="30"/>
  </joint>
  <joint name="pars__jRL" type="continuous">
    <parent link="pars__body"/>
    <child link="pars__rear_left_wheel"/>
    <origin rpy="0     1.5707 0" xyz="-0.3 -0.7  0.3"/>
    <axis xyz="0 0 -1"/>
    <limit effort="1000" velocity="30"/>
  </joint>
  
  <!--                GAZEBO RELATED PART                             -->
 
  <!-- ROS Control plugin for Gazebo -->
  <gazebo>
    <plugin name="gazebo_ros_control" filename="libgazebo_ros_control.so">
      <robotNamespace>/pars</robotNamespace>
      <robotSimType>gazebo_ros_control/DefaultRobotHWSim</robotSimType>
    </plugin>
    <plugin name="imu_plugin" filename="libgazebo_ros_imu.so">
      <alwaysOn>true</alwaysOn>
      <bodyName>pars__body</bodyName>
      <topicName>pars/imu</topicName>
      <serviceName>imu_service</serviceName>
      <gaussianNoise>0.0</gaussianNoise>
      <updateRate>20.0</updateRate>
    </plugin>
  </gazebo>
  
  <transmission name="FRsteer_transmission" type="SimpleTransmission">
    <type>transmission_interface/SimpleTransmission</type>
    <actuator name="FRsteerMotor">
      <hardwareInterface>hardware_interface/EffortJointInterface</hardwareInterface>
      <mechanicalReduction>1</mechanicalReduction>
    </actuator>
    <joint name="pars__jFRsteer">
      <hardwareInterface>hardware_interface/EffortJointInterface</hardwareInterface>
    </joint>
  </transmission>
  <transmission name="FLsteer_transmission" type="SimpleTransmission">
    <type>transmission_interface/SimpleTransmission</type>
    <actuator name="FLsteerMotor">
      <hardwareInterface>hardware_interface/EffortJointInterface</hardwareInterface>
      <mechanicalReduction>1</mechanicalReduction>
    </actuator>
    <joint name="pars__jFLsteer">
      <hardwareInterface>hardware_interface/EffortJointInterface</hardwareInterface>
    </joint>
  </transmission>
  
  <transmission name="FR_transmission" type="SimpleTransmission">
    <type>transmission_interface/SimpleTransmission</type>
    <actuator name="FRMotor">
      <hardwareInterface>hardware_interface/EffortJointInterface</hardwareInterface>
      <mechanicalReduction>1</mechanicalReduction>
    </actuator>
    <joint name="pars__jFR">
      <hardwareInterface>hardware_interface/EffortJointInterface</hardwareInterface>
    </joint>
  </transmission>
  <transmission name="FL_transmission" type="SimpleTransmission">
    <type>transmission_interface/SimpleTransmission</type>
    <actuator name="FLMotor">
      <hardwareInterface>hardware_interface/EffortJointInterface</hardwareInterface>
      <mechanicalReduction>1</mechanicalReduction>
    </actuator>
    <joint name="pars__jFL">
      <hardwareInterface>hardware_interface/EffortJointInterface</hardwareInterface>
    </joint>
  </transmission>
  <transmission name="RR_transmission" type="SimpleTransmission">
    <type>transmission_interface/SimpleTransmission</type>
    <actuator name="RRMotor">
      <hardwareInterface>hardware_interface/EffortJointInterface</hardwareInterface>
      <mechanicalReduction>1</mechanicalReduction>
    </actuator>
    <joint name="pars__jRR">
      <hardwareInterface>hardware_interface/EffortJointInterface</hardwareInterface>
    </joint>
  </transmission>
  <transmission name="RL_transmission" type="SimpleTransmission">
    <type>transmission_interface/SimpleTransmission</type>
    <actuator name="RLMotor">
      <hardwareInterface>hardware_interface/EffortJointInterface</hardwareInterface>
      <mechanicalReduction>1</mechanicalReduction>
    </actuator>
    <joint name="pars__jRL">
      <hardwareInterface>hardware_interface/EffortJointInterface</hardwareInterface>
    </joint>
  </transmission>

</robot>