<?xml version="1.0"?>
<sdf version='1.5'>
  <model name='pars'>
    <static>true</static>
    <!-- Pars body -->
    <link name='body'>
      <pose>0 0 0 0 0 0</pose>
      <inertial>
        <pose>0 0 0 0 0 0</pose>
        <mass>1.47</mass>
        <inertia>
          <ixx>0.011</ixx>
          <ixy>0</ixy>
          <ixz>0</ixz>
          <iyy>0.015</iyy>
          <iyz>0</iyz>
          <izz>0.021</izz>
        </inertia>
      </inertial>
      <collision name='base_link_inertia_collision'>
        <pose>0 -0.03 0.36 0 0 0</pose>
        <geometry>
          <box>
            <size>0.8 1.75 0.56</size>
          </box>
        </geometry>
        <surface>
          <contact>
            <ode>
              <min_depth>0.001</min_depth>
              <max_vel>0</max_vel>
            </ode>
          </contact>
          <friction>
            <ode/>
          </friction>
        </surface>
      </collision>
      <visual name='base_link_inertia_visual'>
        <pose>0 0 0.13 0 0 0</pose>
        <geometry>
          <mesh>
            <scale>0.15 0.15 0.15</scale>
            <uri>model://pars/meshes/pars.stl</uri>
          </mesh>
        </geometry>
        <material>
          <script>
            <name>Gazebo/Red</name>
            <uri>file://media/materials/scripts/gazebo.material</uri>
          </script>
        </material>
      </visual>
      <gravity>1</gravity>
      <velocity_decay/>
      <self_collide>0</self_collide>
    </link>
    
    <link name="front_left_wheel">
        <pose>-0.55 0.69 0.30 0 1.5707 0</pose>
        <collision name="collision">
          <geometry>
            <cylinder>
              <radius>.18</radius>
              <length>.05</length>
            </cylinder>
          </geometry>
        </collision>
        <visual name="visual">
          <geometry>
            <cylinder>
              <radius>.29.32</radius>
              <length>.05</length>
            </cylinder>
          </geometry>
          <material>
            <script>
              <name>Gazebo/Black</name>
              <uri>file://media/materials/scripts/gazebo.material</uri>
            </script>
          </material>
        </visual>
    </link>
    <link name="front_right_wheel">
        <pose>0.55 0.69 0.30 0 1.5707 0</pose>
        <collision name="collision">
          <geometry>
            <cylinder>
              <radius>.18</radius>
              <length>.05</length>
            </cylinder>
          </geometry>
        </collision>
        <visual name="visual">
          <geometry>
            <cylinder>
              <radius>.29.32</radius>
              <length>.05</length>
            </cylinder>
          </geometry>
          <material>
            <script>
              <name>Gazebo/Black</name>
              <uri>file://media/materials/scripts/gazebo.material</uri>
            </script>
          </material>
        </visual>
    </link>
    <link name="rear_left_wheel">
        <pose>-0.30 -0.70 0.30 0 1.5707 0</pose>
        <collision name="collision">
          <geometry>
            <cylinder>
              <radius>.18</radius>
              <length>.05</length>
            </cylinder>
          </geometry>
        </collision>
        <visual name="visual">
          <geometry>
            <cylinder>
              <radius>.29.32</radius>
              <length>.05</length>
            </cylinder>
          </geometry>
          <material>
            <script>
              <name>Gazebo/Black</name>
              <uri>file://media/materials/scripts/gazebo.material</uri>
            </script>
          </material>
        </visual>
    </link>
    <link name="rear_right_wheel">
        <pose>0.30 -0.70 0.30 0 1.5707 0</pose>
        <collision name="collision">
          <geometry>
            <cylinder>
              <radius>.18</radius>
              <length>.05</length>
            </cylinder>
          </geometry>
        </collision>
        <visual name="visual">
          <geometry>
            <cylinder>
              <radius>.29.32</radius>
              <length>.05</length>
            </cylinder>
          </geometry>
          <material>
            <script>
              <name>Gazebo/Black</name>
              <uri>file://media/materials/scripts/gazebo.material</uri>
            </script>
          </material>
        </visual>
    </link>
    
    <link name="FLwheel_steer">
      <pose>-0.55 0.69 0.30 0 1.5707 0</pose>
    </link>
    <link name="FRwheel_steer">
      <pose>0.55 0.69 0.30 0 1.5707 0</pose>
    </link>
    
    <joint name="jFRsteer" type="revolute">
      <parent>body</parent>
      <child>FRwheel_steer</child>
      <axis>
        <xyz>0 0 1</xyz>
        <limit>
          <upper>0.8</upper>
          <lower>-0.8</lower>
        </limit>
        <dynamics>
          <friction>2.0</friction>
        </dynamics>
      </axis>
    </joint>
    <joint name="jFLsteer" type="revolute">
      <parent>body</parent>
      <child>FLwheel_steer</child>
      <axis>
        <xyz>0 0 1</xyz>
        <limit>
          <upper>0.8</upper>
          <lower>-0.8</lower>
        </limit>
        <dynamics>
          <friction>2.0</friction>
        </dynamics>
      </axis>
    </joint>

    <joint name="jFR" type="revolute">
      <parent>FRwheel_steer</parent>
      <child>front_right_wheel</child>
      <axis>
        <xyz>0 1 0</xyz>
      </axis>
    </joint>
    <joint name="jFL" type="revolute">
      <parent>FLwheel_steer</parent>
      <child>front_left_wheel</child>
      <axis>
        <xyz>0 1 0</xyz>
      </axis>
    </joint>

    <joint name="jTR" type="revolute">
        <parent>body</parent>
        <child>rear_right_wheel</child>
        <axis>
            <xyz>0 1 0</xyz>
        </axis>
    </joint>
    <joint name="jTL" type="revolute">
        <parent>body</parent>
        <child>rear_left_wheel</child>
        <axis>
            <xyz>0 1 0</xyz>
        </axis>
    </joint>
    <plugin name="car_plugin" filename="libcar_model.dylib" />
    
    <!--<joint type="revolute2" name="front_left_joint">
      <parent>body</parent>
      <child>front_left_wheel</child>
      <axis xyz="0 0 1">
        <limit lower="0" upper="0" />
      </axis>
      <axis2 xyz="0 1 0" />
      <physics>
        <ode>
          <limit cfm="0.0" erp="0.9" />
        </ode>
      </physics>
    </joint>
    <joint type="revolute2" name="front_right_joint">
      <parent>body</parent>
      <child>front_right_wheel</child>
      <axis xyz="0 0 1">
        <limit lower="0" upper="0" />
      </axis>
      <axis2 xyz="0 1 0" />
      <physics>
        <ode>
          <limit cfm="0.0" erp="0.9" />
        </ode>
      </physics>
    </joint>
    <joint type="revolute2" name="rear_right_joint">
      <parent>body</parent>
      <child>rear_right_wheel</child>
      <axis xyz="0 0 1">
        <limit lower="0" upper="0" />
      </axis>
      <axis2 xyz="0 1 0" />
      <physics>
        <ode>
          <limit cfm="0.0" erp="0.9" />
        </ode>
      </physics>
    </joint>
    <joint type="revolute2" name="rear_left_joint">
      <parent>body</parent>
      <child>rear_left_wheel</child>
      <axis xyz="0 0 1">
        <limit lower="0" upper="0" />
      </axis>
      <axis2 xyz="0 1 0" />
      <physics>
        <ode>
          <limit cfm="0.0" erp="0.9" />
        </ode>
      </physics>
</joint>-->
    
<!--    
    <joint type="revolute" name="rear_left_wheel_hinge">
      <pose>0 0 -0.03 0 0 0</pose>
      <child>rear_left_wheel</child>
      <parent>chassis</parent>
      <axis>
        <xyz>0 1 0</xyz>
      </axis>
    </joint>
    <joint type="revolute" name="rear_right_wheel_hinge">
      <pose>0 0 -0.03 0 0 0</pose>
      <child>rear_right_wheel</child>
      <parent>chassis</parent>
      <axis>
        <xyz>0 1 0</xyz>
      </axis>
    </joint>-->

    
    <!--<link name='imu_link'>
      <pose>0 0 0 0 0 0</pose>
      <inertial>
        <pose>0 0 0 0 0 0</pose>
        <mass>0.015</mass>
        <inertia>
          <ixx>1e-05</ixx>
          <ixy>0</ixy>
          <ixz>0</ixz>
          <iyy>1e-05</iyy>
          <iyz>0</iyz>
          <izz>1e-05</izz>
        </inertia>
      </inertial>
    </link>
    <joint name='imu_joint' type='revolute'>
      <child>imu_link</child>
      <parent>base_link</parent>
      <axis>
        <xyz>1 0 0</xyz>
        <limit>
          <lower>0</lower>
          <upper>0</upper>
          <effort>0</effort>
          <velocity>0</velocity>
        </limit>
        <dynamics>
          <spring_reference>0</spring_reference>
          <spring_stiffness>0</spring_stiffness>
        </dynamics>
        <use_parent_model_frame>1</use_parent_model_frame>
      </axis>
    </joint>
    
    <link name='rotor_0'>
      <pose>0.14745 -0.14525 0.051 0 0 0</pose>
      <inertial>
        <pose>0 0 0 0 0 0</pose>
        <mass>0.005</mass>
        <inertia>
          <ixx>9.75e-07</ixx>
          <ixy>0</ixy>
          <ixz>0</ixz>
          <iyy>0.000273104</iyy>
          <iyz>0</iyz>
          <izz>0.000274004</izz>
        </inertia>
      </inertial>
      <collision name='rotor_0_collision'>
        <pose>0 0 0 0 0 0</pose>
        <geometry>
          <cylinder>
            <length>0.005</length>
            <radius>0.128</radius>
          </cylinder>
        </geometry>
        <surface>
          <contact>
            <ode/>
          </contact>
          <friction>
            <ode/>
          </friction>
        </surface>
      </collision>
      <visual name='rotor_0_visual'>
        <pose>-0.14745 -0.14525 -0.051 0 0 0</pose>
        <geometry>
          <mesh>
            <scale>1 1 1</scale>
            <uri>model://solo/meshes/solo_prop_ccw.stl</uri>
          </mesh>
        </geometry>
        <material>
          <script>
            <name>Gazebo/Blue</name>
            <uri>file://media/materials/scripts/gazebo.material</uri>
          </script>
        </material>
      </visual>
      <gravity>1</gravity>
      <velocity_decay/>
      <self_collide>0</self_collide>
    </link>
    <joint name='rotor_0_joint' type='revolute'>
      <child>rotor_0</child>
      <parent>base_link</parent>
      <axis>
        <xyz>0 0 1</xyz>
        <limit>
          <lower>-1e+16</lower>
          <upper>1e+16</upper>
        </limit>
        <dynamics>
          <spring_reference>0</spring_reference>
          <spring_stiffness>0</spring_stiffness>
        </dynamics>
        <use_parent_model_frame>1</use_parent_model_frame>
      </axis>
    </joint>
    
    <plugin name='rosbag' filename='libgazebo_multirotor_base_plugin.so'>
      <robotNamespace></robotNamespace>
      <linkName>base_link</linkName>
      <rotorVelocitySlowdownSim>10</rotorVelocitySlowdownSim>
    </plugin>
    
    <plugin name='gazebo_imu_plugin' filename='libgazebo_imu_plugin.so'>
      <robotNamespace></robotNamespace>
      <linkName>imu_link</linkName>
      <imuTopic>/imu</imuTopic>
      <gyroscopeNoiseDensity>0.0003394</gyroscopeNoiseDensity>
      <gyroscopeRandomWalk>3.8785e-05</gyroscopeRandomWalk>
      <gyroscopeBiasCorrelationTime>1000.0</gyroscopeBiasCorrelationTime>
      <gyroscopeTurnOnBiasSigma>0.0087</gyroscopeTurnOnBiasSigma>
      <accelerometerNoiseDensity>0.004</accelerometerNoiseDensity>
      <accelerometerRandomWalk>0.006</accelerometerRandomWalk>
      <accelerometerBiasCorrelationTime>300.0</accelerometerBiasCorrelationTime>
      <accelerometerTurnOnBiasSigma>0.196</accelerometerTurnOnBiasSigma>
    </plugin>
    -->

  </model>
</sdf>
